{"uuid": "0fad5aaf-c2ea-4b1b-a21a-371feda5c133", "children": ["a321a21d-fa50-4bf7-a6aa-4cd665e9d6e7"], "befores": [{"name": "start_appium_session", "status": "broken", "statusDetails": {"message": "urllib3.exceptions.ProtocolError: ('Connection aborted.', ConnectionResetError(10054, '远程主机强迫关闭了一个现有的连接。', None, 10054, None))\n", "trace": "  File \"C:\\Python38\\lib\\site-packages\\pluggy\\callers.py\", line 187, in _multicall\n    res = hook_impl.function(*args)\n  File \"C:\\Python38\\lib\\site-packages\\_pytest\\fixtures.py\", line 1126, in pytest_fixture_setup\n    result = call_fixture_func(fixturefunc, request, kwargs)\n  File \"C:\\Python38\\lib\\site-packages\\_pytest\\fixtures.py\", line 925, in call_fixture_func\n    fixture_result = next(generator)\n  File \"E:\\UI_Auto\\TestCases\\conftest.py\", line 44, in start_appium_session\n    driver = webdriver.Remote('http://127.0.0.1:4723/wd/hub', device_info)\n  File \"C:\\Python38\\lib\\site-packages\\appium\\webdriver\\webdriver.py\", line 147, in __init__\n    super(WebDriver, self).__init__(\n  File \"C:\\Python38\\lib\\site-packages\\selenium\\webdriver\\remote\\webdriver.py\", line 157, in __init__\n    self.start_session(capabilities, browser_profile)\n  File \"C:\\Python38\\lib\\site-packages\\appium\\webdriver\\webdriver.py\", line 227, in start_session\n    response = self.execute(RemoteCommand.NEW_SESSION, parameters)\n  File \"C:\\Python38\\lib\\site-packages\\selenium\\webdriver\\remote\\webdriver.py\", line 319, in execute\n    response = self.command_executor.execute(driver_command, params)\n  File \"C:\\Python38\\lib\\site-packages\\selenium\\webdriver\\remote\\remote_connection.py\", line 374, in execute\n    return self._request(command_info[0], url, body=data)\n  File \"C:\\Python38\\lib\\site-packages\\selenium\\webdriver\\remote\\remote_connection.py\", line 397, in _request\n    resp = self._conn.request(method, url, body=body, headers=headers)\n  File \"C:\\Python38\\lib\\site-packages\\urllib3\\request.py\", line 70, in request\n    return self.request_encode_body(method, url, fields=fields,\n  File \"C:\\Python38\\lib\\site-packages\\urllib3\\request.py\", line 150, in request_encode_body\n    return self.urlopen(method, url, **extra_kw)\n  File \"C:\\Python38\\lib\\site-packages\\urllib3\\poolmanager.py\", line 324, in urlopen\n    response = conn.urlopen(method, u.request_uri, **kw)\n  File \"C:\\Python38\\lib\\site-packages\\urllib3\\connectionpool.py\", line 637, in urlopen\n    retries = retries.increment(method, url, error=e, _pool=self,\n  File \"C:\\Python38\\lib\\site-packages\\urllib3\\util\\retry.py\", line 368, in increment\n    raise six.reraise(type(error), error, _stacktrace)\n  File \"C:\\Python38\\lib\\site-packages\\urllib3\\packages\\six.py\", line 685, in reraise\n    raise value.with_traceback(tb)\n  File \"C:\\Python38\\lib\\site-packages\\urllib3\\connectionpool.py\", line 597, in urlopen\n    httplib_response = self._make_request(conn, method, url,\n  File \"C:\\Python38\\lib\\site-packages\\urllib3\\connectionpool.py\", line 384, in _make_request\n    six.raise_from(e, None)\n  File \"<string>\", line 2, in raise_from\n  File \"C:\\Python38\\lib\\site-packages\\urllib3\\connectionpool.py\", line 380, in _make_request\n    httplib_response = conn.getresponse()\n  File \"C:\\Python38\\lib\\http\\client.py\", line 1322, in getresponse\n    response.begin()\n  File \"C:\\Python38\\lib\\http\\client.py\", line 303, in begin\n    version, status, reason = self._read_status()\n  File \"C:\\Python38\\lib\\http\\client.py\", line 264, in _read_status\n    line = str(self.fp.readline(_MAXLINE + 1), \"iso-8859-1\")\n  File \"C:\\Python38\\lib\\socket.py\", line 669, in readinto\n    return self._sock.recv_into(b)\n"}, "start": 1635412423188, "stop": 1635412423654}], "start": 1635412423188, "stop": 1635412424132}